Workbook

Sheet 00_README
B1: Data workbook — circular accounting capability study
B4: HOW TO USE THIS WORKBOOK
A6: 1 | B6: Read 01_SampleSize first. It tells you what your achieved n allows you to claim, and it flags a power problem in the manuscript's current Approach A that you should fix before submission.
A7: 2 | B7: Enter data on sheet 04_DATA only. One row per respondent. Do not insert, delete or reorder columns — the R script in analysis_seminr.R matches these names exactly.
A8: 3 | B8: Column meanings are in 02_Codebook. Item wordings are in 03_Items. Categorical codes are in 05_ValueLabels.
A9: 4 | B9: Track fieldwork progress in 06_SampleTracker. The response accounting it produces is required for Table 9 of the manuscript — reviewers will ask for it.
A10: 5 | B10: 07_QualityChecks runs live per-row diagnostics as you enter data. Fix problems during fieldwork, not afterwards.
A11: 6 | B11: When complete, save 04_DATA as data.csv (UTF-8) in the same folder as analysis_seminr.R and run it.
B13: CRITICAL — CHECK THESE BEFORE YOU ANALYSE ANYTHING
A15: a | B15: CAC_GLOBAL and CVCP_GLOBAL are single-item global measures of the two formative higher-order constructs. Redundancy analysis is impossible without them and CANNOT be done after the fact. If you did not field them, leave the columns empty and report the failure to establish convergent validity of the formative constructs as a limitation. Do not omit it silently.
A16: b | B16: Check CGQ dispersion the moment you have the data (07_QualityChecks computes it). The entire design rests on governance quality varying widely within one network and one regulatory environment. If the SD is small, the interaction cannot be detected, and you must say so BEFORE reporting any null.
A17: c | B17: All CVCP items must be worded so that HIGHER = BETTER. The loss items should read "reduction in…". If any was fielded as "quantity of waste", reverse-code it and record that you did.
A18: d | B18: IS2 and IS3 are the double-barrelled items your Section 5.5 flags as below threshold and never revised. If they were fielded as written, report their psychometrics rather than quietly dropping them.
A19: e | B19: MK1–MK3 must be Miller and Simmering's (2023) attitude-toward-blue items reproduced verbatim. A paraphrased marker forfeits the warrant for using a validated one.
B21: WHAT NOT TO DO
A23: ✗ | B23: Do not delete cases flagged as long-string, fast-completion or multivariate outliers. These are flag-and-test, not delete. Deleting them without reporting the sensitivity analysis is the most common source of an undisclosed specification search in this literature.
A24: ✗ | B24: Do not add a CAC → CVCP path "to see if it is significant". H9's claim is that the effect is entirely indirect. If you estimate it you must report it, and the theoretical claim changes.
A25: ✗ | B25: Do not run Harman's single-factor test. Your Section 6 pre-specifies that it is not used.
A26: ✗ | B26: Do not run the producer-versus-processor multi-group comparison. With ~70 processors it needs β ≥ 0.30 to be detectable, and your manuscript already states it will not be conducted and why.
A27: ✗ | B27: Do not judge the interaction effect size against Cohen's 0.02/0.15/0.35. Use the interaction-specific benchmarks 0.005/0.01/0.025, as Table 8 pre-specifies.

Sheet 01_SampleSize
A1: Required number of respondents
A2: Figures recomputed from the non-central F distribution; they reproduce Table 6 of the manuscript exactly (Approach A f²=0.05 at power .90 → 434; minimum 346≈350 at power .80; Approach B β=0.11 → 511).
A4: A. The design target (unchanged from the manuscript)
A5: Approach | B5: Basis | C5: Requirement | D5: Status
A6: A. A-priori power | B6: F-test for R² deviation from zero; 11 predictors on CVCI; f²=0.05; power .90; α=.05 | C6: 434 | D6: satisfied at n≥434
A7: B. Inverse square root | B7: Kock and Hadaya (2018); smallest expected path β=0.11; power .80 | C7: 511 | D7: BINDING
A8: C. Model complexity | B8: ≈96 free parameters at 5:1 for the covariance-based robustness check | C8: 480 | D8: satisfied at n≥480
A9: D. Multi-group analysis | B9: Two groups each estimable at β≈0.15–0.20 | C9: 490–550 | D9: satisfied at n≥490
A10: ADOPTED TARGET | C10: 520
A11: Minimum acceptable | B11: Approach A at power .80 (computed: 346) | C11: 350
A12: Recommended | C12: 450
A15: B. What your achieved n actually buys you
A16: Find your row. This is the honest basis for what you can claim.
A17: Achieved n | B17: Smallest detectable path β (power .80) | C17: Smallest detectable interaction f² (power .80) | D17: Approach A power at f²=0.05 | E17: MGA viable? | F17: Verdict
A18: 200 | B18: 0.176 | C18: 0.0398 | D18: 0.497 | E18: no | F18: Insufficient. Below the stated minimum.
A19: 250 | B19: 0.157 | C19: 0.0318 | D19: 0.62 | E19: no | F19: Insufficient.
A20: 300 | B20: 0.144 | C20: 0.0265 | D20: 0.723 | E20: no | F20: Below minimum. Interaction test weak.
A21: 350 | B21: 0.133 | C21: 0.0226 | D21: 0.806 | E21: yes | F21: Minimum acceptable. State the limitation.
A22: 400 | B22: 0.124 | C22: 0.0198 | D22: 0.868 | E22: yes | F22: Acceptable.
A23: 450 | B23: 0.117 | C23: 0.0175 | D23: 0.913 | E23: yes | F23: Recommended level reached.
A24: 480 | B24: 0.113 | C24: 0.0165 | D24: 0.933 | E24: yes | F24: Approach C satisfied.
A25: 511 | B25: 0.11 | C25: 0.0155 | D25: 0.949 | E25: yes | F25: Binding Approach B satisfied.
A26: 520 | B26: 0.109 | C26: 0.0152 | D26: 0.953 | E26: yes | F26: DESIGN TARGET MET.
A27: 600 | B27: 0.101 | C27: 0.0132 | D27: 0.978 | E27: yes | F27: Comfortable.
A28: 700 | B28: 0.094 | C28: 0.0112 | D28: 0.992 | E28: yes | F28: Comfortable; medium interaction detectable.
A31: C. A power problem in the manuscript you should fix
A32: Your Section 5.4 argues, correctly, that "the binding quantity is the interaction, not the largest path" and that "planning against a medium main effect would under-power the central test". Approach A then plans against f²=0.05 on the overall R² of CVCI — which is a MAIN-EFFECT quantity. Judged against the interaction-specific benchmarks your own Table 8 pre-specifies (0.005 small / 0.01 medium / 0.025 large), the design target of 520 gives power .95 for a LARGE interaction but only .62 for a MEDIUM one and .36 for a SMALL one. The argument is right; the number does not follow it through. A reviewer who checks will notice.
A34: Achieved n | B34: Power at f²=0.005 (small) | C34: Power at f²=0.010 (medium) | D34: Power at f²=0.015 | E34: Power at f²=0.025 (large) | F34: Smallest f² at power .80
A35: 350 | B35: 0.261 | C35: 0.463 | D35: 0.627 | E35: 0.839 | F35: 0.0226
A36: 400 | B36: 0.292 | C36: 0.514 | D36: 0.686 | E36: 0.884 | F36: 0.0198
A37: 450 | B37: 0.322 | C37: 0.562 | D37: 0.736 | E37: 0.917 | F37: 0.0175
A38: 480 | B38: 0.34 | C38: 0.59 | D38: 0.764 | E38: 0.933 | F38: 0.0165
A39: 511 | B39: 0.358 | C39: 0.617 | D39: 0.789 | E39: 0.946 | F39: 0.0155
A40: 520 | B40: 0.363 | C40: 0.624 | D40: 0.796 | E40: 0.949 | F40: 0.0152
A41: 600 | B41: 0.409 | C41: 0.686 | D41: 0.85 | E41: 0.972 | F41: 0.0132
A43: The fix — add this sentence to Section 5.4, and honour it in Section 7
A44: "Because the interaction is the binding quantity, we additionally report the minimum detectable interaction effect size. At the achieved sample of n = [___], the design attains power .80 for an interaction f² of [___] or larger, judged against the interaction-specific benchmarks of 0.005, 0.010 and 0.025. A true interaction below that value would not reliably be detected, and a null result is therefore interpreted accordingly." This costs you two sentences and converts a vulnerability into evidence of methodological care. If the interaction turns out null, it is also what prevents the null being over-read as evidence of absence.

Sheet 02_Codebook
A1: Codebook — 68 columns, in the exact order required by analysis_seminr.R
A3: # | B3: Column name | C3: Label | D3: Type | E3: Allowed values | F3: Notes
A4: 1 | B4: ID | C4: Respondent identifier | D4: text | E4: unique | F4: Required. Any unique code.
A5: 2 | B5: DATE | C5: Date of interview | D5: date | E5: yyyy-mm-dd | F5: Required.
A6: 3 | B6: ENUM | C6: Enumerator identifier | D6: text | F6: Required — needed for the enumerator-effects robustness check.
A7: 4 | B7: DUR_min | C7: Interview duration in minutes | D7: integer | E7: >0 | F7: Required — needed for the fast-completion flag.
A8: 5 | B8: STRATUM | C8: Sampling stratum | D8: integer | E8: 1–6 | F8: See 05_ValueLabels. Required for Table 9 response accounting.
A9: 6 | B9: TIER | C9: Network position | D9: integer | E9: 1–4 | F9: See 05_ValueLabels. Used as the MGA grouping variable, NOT as a covariate.
A10: 7 | B10: SCR1 | C10: Keeps or supervises records? | D10: integer | E10: 0/1 | F10: Screening. Must be 1 to be eligible.
A11: 8 | B11: SCR2 | C11: Participates in pricing / disposal decisions? | D11: integer | E11: 0/1 | F11: Screening. Must be 1 to be eligible.
A12: 9 | B12: SCR3 | C12: Seasons in this role | D12: integer | E12: >=0 | F12: Screening. Must be >=3 (the outcome items are change over three seasons).
A13: 10 | B13: SCR4 | C13: Self-described role | D13: integer | E13: 1–6 | F13: Assigns STRATUM. See 05_ValueLabels.
A14: 11 | B14: CAC1 | C14: Circular accounting capability item 1 | D14: integer | E14: 1–7 | F14: Focal. Items 1–3 measurement, 4–6 loss costing, 7–9 recovery valuation. 7-point; 1 = not at all … 7 = to a very great extent
A15: 12 | B15: CAC2 | C15: Circular accounting capability item 2 | D15: integer | E15: 1–7 | F15: Focal. Items 1–3 measurement, 4–6 loss costing, 7–9 recovery valuation. 7-point; 1 = not at all … 7 = to a very great extent
A16: 13 | B16: CAC3 | C16: Circular accounting capability item 3 | D16: integer | E16: 1–7 | F16: Focal. Items 1–3 measurement, 4–6 loss costing, 7–9 recovery valuation. 7-point; 1 = not at all … 7 = to a very great extent
A17: 14 | B17: CAC4 | C17: Circular accounting capability item 4 | D17: integer | E17: 1–7 | F17: Focal. Items 1–3 measurement, 4–6 loss costing, 7–9 recovery valuation. 7-point; 1 = not at all … 7 = to a very great extent
A18: 15 | B18: CAC5 | C18: Circular accounting capability item 5 | D18: integer | E18: 1–7 | F18: Focal. Items 1–3 measurement, 4–6 loss costing, 7–9 recovery valuation. 7-point; 1 = not at all … 7 = to a very great extent
... A70: 67 | B70: OBJ3 | C70: Realised price ÷ district modal price | D70: decimal | E70: >0 | F70: Objective subsample only.
A71: 68 | B71: NOTES | C71: Enumerator notes | D71: text | F71: Optional. Not analysed.

Sheet 03_Items
A1: The 46-item instrument
A2: RECONSTRUCTION — the instrument table is not present in JCLP_11_08_26.docx. These wordings satisfy every constraint the manuscript states (counts, dimensions, the 22/11/10/3 source split, and the item labels named in Section 5.5), but they are NOT retrieved from your file. Replace column F with your fielded wordings and keep the IDs aligned.
A4: ID | B4: Construct | C4: Dimension | D4: Source | E4: R3 reworded? | F4: Item wording | G4: Watch for
A5: CAC1 | B5: CAC | C5: Material and resource-flow measurement | D5: AS | F5: We keep a written or electronic record of the quantity of raw material we take in each season.
A6: CAC2 | B6: CAC | C6: Material and resource-flow measurement | D6: AS | E6: yes | F6: We write down how much of what we handle is rejected, downgraded or lost. | G6: The one item quoted in your manuscript.
A7: CAC3 | B7: CAC | C7: Material and resource-flow measurement | D7: AS | F7: We record what happens to the material that does not become saleable product — where it goes and who takes it.
A8: CAC4 | B8: CAC | C8: Loss and waste costing | D8: AS | F8: We work out what the material we lose or reject cost us to buy or to produce.
A9: CAC5 | B9: CAC | C9: Loss and waste costing | D9: AS | F9: We know what the rejected or lost material would have earned had it been sold as product.
A10: CAC6 | B10: CAC | C10: Loss and waste costing | D10: ND | F10: We keep the cost of losses separate from our general operating costs rather than absorbing it into overall cost.
A11: CAC7 | B11: CAC | C11: Recovery and circular investment evaluation | D11: ND | F11: Before deciding whether to recover a by-product or residue, we estimate what it could earn. | G11: New dimension; expert disagreement concentrated here.
A12: CAC8 | B12: CAC | C12: Recovery and circular investment evaluation | D12: ND | F12: We compare the cost of recovering a residue against the cost of disposing of it. | G12: New dimension.
A13: CAC9 | B13: CAC | C13: Recovery and circular investment evaluation | D13: ND | F13: When we consider equipment or capacity for processing residues, we work out whether the investment would pay back. | G13: New dimension.
A14: CIT1 | B14: CIT | C14: — | D14: AV | F14: Partners we deal with can see how much material is rejected or lost at our stage.
A15: CIT2 | B15: CIT | C15: — | D15: AV | F15: We can see how much material is rejected or lost at the stages before and after us.
A16: CIT3 | B16: CIT | C16: — | D16: AV | E16: yes | F16: Information about recoverable residues and by-products reaches the people who could use them, in time for them to act. | G16: Reached 0.975 after rewording.
A17: CIT4 | B17: CIT | C17: — | D17: AS | F17: Information about material flows and losses in this chain is accurate and reliable enough to base a decision on.
A18: CIT5 | B18: CIT | C18: — | D18: ND | F18: We can see how the money paid for the final product is divided among the actors in this chain. | G18: Price rather than material information — most likely to behave differently.
A19: CGQ1 | B19: CGQ | C19: Responsibility allocation | D19: ND | E19: yes | F19: It is clear which party is answerable when material is lost or spoiled between us and our partners. | G19: The construct's diagnostic core.
A20: CGQ2 | B20: CGQ | C20: Joint monitoring and verification | D20: AV | F20: Our partners and we jointly check the quantities and quality recorded when material changes hands.
A21: CGQ3 | B21: CGQ | C21: Codified standards | D21: AS | F21: What counts as an acceptable level of loss is agreed and recorded with our partners.
A22: CGQ4 | B22: CGQ | C22: Participatory decision-making | D22: AV | F22: We are able to take part in decisions that affect how material and losses are handled in this chain.
A23: CGQ5 | B23: CGQ | C23: Participatory decision-making | D23: AV | F23: Our views are taken into account when the terms of trade in this chain are set.
A24: CGQ6 | B24: CGQ | C24: Enforceable commitment | D24: AV | E24: yes | F24: Commitments our partners make about handling, collection or payment are honoured, and there are consequences if they are not. | G24: Low ρA here attenuates the interaction directly.
A25: CVCI1 | B25: CVCI | C25: — | D25: AV | F25: We plan jointly with partners how material that would otherwise be wasted will be collected and moved.
A26: CVCI2 | B26: CVCI | C26: — | D26: AV | E26: yes | F26: We coordinate the timing of our operations with partners so that recoverable material is handled before it deteriorates.
A27: CVCI3 | B27: CVCI | C27: — | D27: AV | F27: We share equipment, storage or transport with partners for handling residues and by-products.
A28: CVCI4 | B28: CVCI | C28: — | D28: AV | F28: We and our partners exchange the information needed to route recoverable material to where it can be used. | G28: Watch for HTMT overlap with CIT.
A29: CVCI5 | B29: CVCI | C29: — | D29: AS | F29: We agree with partners in advance how the proceeds from recovered material will be shared.
A30: CVCI6 | B30: CVCI | C30: — | D30: AV | F30: We work together with partners to find new uses for material that used to be discarded.
A31: CVCP1 | B31: CVCP | C31: Economic | D31: AV | F31: Income earned from selling by-products or residues that were previously discarded.
A32: CVCP2 | B32: CVCP | C32: Economic | D32: AV | F32: Savings from reusing material internally instead of buying new.
A33: CVCP3 | B33: CVCP | C33: Economic | D33: AS | F33: The price we realise for our main product.
A34: CVCP4 | B34: CVCP | C34: Economic | D34: AS | F34: Reduction in the cost of disposing of waste.
A35: CVCP5 | B35: CVCP | C35: Environmental | D35: AV | F35: Reduction in the quantity of material leaving our operation as waste.
A36: CVCP6 | B36: CVCP | C36: Environmental | D36: AV | F36: Reduction in the share of what we handle that is lost or spoiled.
A37: CVCP7 | B37: CVCP | C37: Environmental | D37: AS | F37: Reduction in the energy and water used per unit of product.
A38: CVCP8 | B38: CVCP | C38: Environmental | D38: ND | F38: Reduction in the quantity of residues sent to landfill, burned or dumped.
A39: CVCP9 | B39: CVCP | C39: Social | D39: ND | F39: The share of the value from recovered material that reaches the producers who supplied it. | G39: Weak SOC weight is a FINDING, not a failure.
A40: CVCP10 | B40: CVCP | C40: Social | D40: ND | F40: Employment or paid work created by handling and processing recovered material.
A41: CVCP11 | B41: CVCP | C41: Social | D41: ND | F41: Fairness with which the gains from reducing losses are shared among the actors in this chain.
...

Sheet 04_DATA
A1: ID | B1: DATE | C1: ENUM | D1: DUR_min | E1: STRATUM | F1: TIER | G1: SCR1 | H1: SCR2 | I1: SCR3 | J1: SCR4 | K1: CAC1 | L1: CAC2 | M1: CAC3 | N1: CAC4 | O1: CAC5 | P1: CAC6 | Q1: CAC7 | R1: CAC8 | S1: CAC9 | T1: CIT1 | U1: CIT2 | V1: CIT3 | W1: CIT4 | X1: CIT5 | Y1: CGQ1 | Z1: CGQ2 | AA1: CGQ3 | AB1: CGQ4 | AC1: CGQ5 | AD1: CGQ6 | AE1: CVCI1 | AF1: CVCI2 | AG1: CVCI3 | AH1: CVCI4 | AI1: CVCI5 | AJ1: CVCI6 | AK1: CVCP1 | AL1: CVCP2 | AM1: CVCP3 | AN1: CVCP4 | AO1: CVCP5 | AP1: CVCP6 | AQ1: CVCP7 | AR1: CVCP8 | AS1: CVCP9 | AT1: CVCP10 | AU1: CVCP11 | AV1: DTC1 | AW1: DTC2 | AX1: DTC3 | AY1: IS1 | AZ1: IS2 | BA1: IS3 | BB1: MK1 | BC1: MK2 | BD1: MK3 | BE1: CAC_GLOBAL | BF1: CVCP_GLOBAL | BG1: SIZE_n | BH1: AGE_yr | BI1: VOL_t | BJ1: EDU | BK1: AFF | BL1: OBJ1 | BM1: OBJ2_qty | BN1: OBJ2_val | BO1: OBJ3 | BP1: NOTES

Sheet 05_ValueLabels
A1: Categorical coding
A3: Variable | B3: Code | C3: Label | D3: Note
A4: STRATUM | B4: 1 | C4: Producers, non-affiliated | D4: Target 180 (34.6%). MGA group: upstream.
A5: STRATUM | B5: 2 | C5: Producers, producer-organisation members | D5: Target 120 (23.1%). MGA group: upstream with collective governance.
A6: STRATUM | B6: 3 | C6: Aggregators, traders, commission agents | D6: Target 80 (15.4%). The information-asymmetry tier.
A7: STRATUM | B7: 4 | C7: Processors and common facility centres | D7: Target 70 (13.5%). Manufacturing and recovery actors; deliberately over-sampled.
A8: STRATUM | B8: 5 | C8: Retailers and institutional buyers | D8: Target 40 (7.7%). Downstream price-formation tier.
A9: STRATUM | B9: 6 | C9: Network support institutions | D9: Target 30 (5.8%). EXCLUDED from group analysis.
A10: TIER | B10: 1 | C10: Upstream producer | D10: Strata 1–2
A11: TIER | B11: 2 | C11: Midstream intermediary | D11: Stratum 3
A12: TIER | B12: 3 | C12: Processing / recovery | D12: Stratum 4
A13: TIER | B13: 4 | C13: Downstream buyer | D13: Stratum 5
A14: TIER | B14: (blank) | C14: Support institutions | D14: Stratum 6 — leave TIER blank; excluded from MGA.
A15: EDU | B15: 1 | C15: No formal schooling
A16: EDU | B16: 2 | C16: Primary
A17: EDU | B17: 3 | C17: Secondary
A18: EDU | B18: 4 | C18: Higher secondary
A19: EDU | B19: 5 | C19: Graduate
A20: EDU | B20: 6 | C20: Postgraduate
A21: AFF | B21: 0 | C21: Not a member of a producer organisation or cooperative
A22: AFF | B22: 1 | C22: Member of a producer organisation or cooperative | D22: MGA grouping variable.
A23: SCR1 | B23: 0 | C23: No — not eligible | D23: Exclude the case.
A24: SCR1 | B24: 1 | C24: Yes — keeps or supervises records
A25: SCR2 | B25: 0 | C25: No — not eligible | D25: Exclude the case.
A26: SCR2 | B26: 1 | C26: Yes — participates in pricing / disposal decisions
A27: SCR4 | B27: 1–6 | C27: Same coding as STRATUM | D27: Self-described role; used to assign STRATUM.

Sheet 06_SampleTracker
A1: Fieldwork tracker and response accounting (feeds Table 9)
A2: Enter columns C–G. Everything else calculates. Reviewers will ask for this reconciliation.
A4: Stratum | B4: Target | C4: Contacted | D4: Refused | E4: Screened out | F4: Incomplete | G4: Valid | H4: Response rate | I4: % of achieved | J4: Shortfall vs target
A5: 1 Producers, non-affiliated | B5: 180 | H5: =IF(C5=0,"",G5/C5) | I5: =IF($G$11=0,"",G5/$G$11) | J5: =G5-B5
A6: 2 Producers, PO members | B6: 120 | H6: =IF(C6=0,"",G6/C6) | I6: =IF($G$11=0,"",G6/$G$11) | J6: =G6-B6
A7: 3 Aggregators, traders, agents | B7: 80 | H7: =IF(C7=0,"",G7/C7) | I7: =IF($G$11=0,"",G7/$G$11) | J7: =G7-B7
A8: 4 Processors and CFCs | B8: 70 | H8: =IF(C8=0,"",G8/C8) | I8: =IF($G$11=0,"",G8/$G$11) | J8: =G8-B8
A9: 5 Retailers and institutional buyers | B9: 40 | H9: =IF(C9=0,"",G9/C9) | I9: =IF($G$11=0,"",G9/$G$11) | J9: =G9-B9
A10: 6 Network support institutions | B10: 30 | H10: =IF(C10=0,"",G10/C10) | I10: =IF($G$11=0,"",G10/$G$11) | J10: =G10-B10
A11: TOTAL | B11: =SUM(B5:B10) | C11: =SUM(C5:C10) | D11: =SUM(D5:D10) | E11: =SUM(E5:E10) | F11: =SUM(F5:F10) | G11: =SUM(G5:G10) | H11: =IF(C11=0,"",G11/C11) | J11: =G11-B11
A13: Achieved n verdict
A14: Achieved valid n | B14: =G11
A15: Smallest detectable path β at power .80 | B15: =IF(G11=0,"",2.486/SQRT(G11))
A16: Approach A satisfied (>=434) | B16: =IF(G11=0,"",IF(G11>=434,"YES","NO"))
A17: Approach B satisfied — BINDING (>=511) | B17: =IF(G11=0,"",IF(G11>=511,"YES","NO"))
A18: Approach C satisfied (>=480) | B18: =IF(G11=0,"",IF(G11>=480,"YES","NO"))
A19: Above stated minimum (>=350) | B19: =IF(G11=0,"",IF(G11>=350,"YES","BELOW MINIMUM"))
A20: MGA viable (smallest group >=100) | B20: Check group sizes on 07_QualityChecks
A22: If Approach B is not satisfied, do not delete the derivation from Section 5.4. Report the achieved n against all four approaches and add the minimum-detectable-interaction sentence from 01_SampleSize. Computing power against the interaction rather than the largest path is a strength; concealing a shortfall is not.

Sheet 07_QualityChecks
A1: Live per-row diagnostics and construct dispersion
A2: Formulas reference 04_DATA rows 2:1001. Flags are FLAG-AND-TEST, not delete — except eligibility and full straight-lining, which are exclusions under the pre-specified rules.
A4: Row | B4: ID | C4: Eligible? | D4: Missing focal items | E4: % missing | F4: Straight-lining | G4: Fast completion | H4: Action | J4: Construct dispersion — CHECK CGQ FIRST
A5: 2 | B5: =IF('04_DATA'!A2="","",'04_DATA'!A2) | C5: =IF('04_DATA'!A2="","",IF(AND('04_DATA'!G2=1,'04_DATA'!H2=1,'04_DATA'!I2>=3),"eligible","EXCLUDE")) | D5: =IF('04_DATA'!A2="","",37-COUNT('04_DATA'!$K2:$AU2)) | E5: =IF('04_DATA'!A2="","",(37-COUNT('04_DATA'!$K2:$AU2))/37) | F5: =IF('04_DATA'!A2="","",IF(AND(COUNT('04_DATA'!$K2:$AU2)=37,COUNTIF('04_DATA'!$K2:$AU2,INDEX('04_DATA'!$K2:$AU2,1))=37),"EXCLUDE","ok")) | G5: =IF('04_DATA'!A2="","",IF('04_DATA'!D2<PERCENTILE('04_DATA'!$D$2:$D$1001,0.05),"FLAG","ok")) | H5: =IF('04_DATA'!A2="","",IF(OR(C5="EXCLUDE",F5="EXCLUDE"),"Exclude under pre-specified rule",IF(E5>0.15,"Exclude: >15% missing",IF(G5="FLAG","Retain; test in robustness battery","Retain")))) | J5: Construct | K5: Mean | L5: SD | M5: Min | N5: Max | O5: Interpretation
A6: 3 | B6: =IF('04_DATA'!A3="","",'04_DATA'!A3) | C6: =IF('04_DATA'!A3="","",IF(AND('04_DATA'!G3=1,'04_DATA'!H3=1,'04_DATA'!I3>=3),"eligible","EXCLUDE")) | D6: =IF('04_DATA'!A3="","",37-COUNT('04_DATA'!$K3:$AU3)) | E6: =IF('04_DATA'!A3="","",(37-COUNT('04_DATA'!$K3:$AU3))/37) | F6: =IF('04_DATA'!A3="","",IF(AND(COUNT('04_DATA'!$K3:$AU3)=37,COUNTIF('04_DATA'!$K3:$AU3,INDEX('04_DATA'!$K3:$AU3,1))=37),"EXCLUDE","ok")) | G6: =IF('04_DATA'!A3="","",IF('04_DATA'!D3<PERCENTILE('04_DATA'!$D$2:$D$1001,0.05),"FLAG","ok")) | H6: =IF('04_DATA'!A3="","",IF(OR(C6="EXCLUDE",F6="EXCLUDE"),"Exclude under pre-specified rule",IF(E6>0.15,"Exclude: >15% missing",IF(G6="FLAG","Retain; test in robustness battery","Retain")))) | J6: Circular accounting capability | K6: =IFERROR(AVERAGE('04_DATA'!$K$2:$S$1001),"") | L6: =IFERROR(STDEV('04_DATA'!$K$2:$S$1001),"") | M6: =IFERROR(MIN('04_DATA'!$K$2:$S$1001),"") | N6: =IFERROR(MAX('04_DATA'!$K$2:$S$1001),"")
A7: 4 | B7: =IF('04_DATA'!A4="","",'04_DATA'!A4) | C7: =IF('04_DATA'!A4="","",IF(AND('04_DATA'!G4=1,'04_DATA'!H4=1,'04_DATA'!I4>=3),"eligible","EXCLUDE")) | D7: =IF('04_DATA'!A4="","",37-COUNT('04_DATA'!$K4:$AU4)) | E7: =IF('04_DATA'!A4="","",(37-COUNT('04_DATA'!$K4:$AU4))/37) | F7: =IF('04_DATA'!A4="","",IF(AND(COUNT('04_DATA'!$K4:$AU4)=37,COUNTIF('04_DATA'!$K4:$AU4,INDEX('04_DATA'!$K4:$AU4,1))=37),"EXCLUDE","ok")) | G7: =IF('04_DATA'!A4="","",IF('04_DATA'!D4<PERCENTILE('04_DATA'!$D$2:$D$1001,0.05),"FLAG","ok")) | H7: =IF('04_DATA'!A4="","",IF(OR(C7="EXCLUDE",F7="EXCLUDE"),"Exclude under pre-specified rule",IF(E7>0.15,"Exclude: >15% missing",IF(G7="FLAG","Retain; test in robustness battery","Retain")))) | J7: Circular information transparency | K7: =IFERROR(AVERAGE('04_DATA'!$T$2:$X$1001),"") | L7: =IFERROR(STDEV('04_DATA'!$T$2:$X$1001),"") | M7: =IFERROR(MIN('04_DATA'!$T$2:$X$1001),"") | N7: =IFERROR(MAX('04_DATA'!$T$2:$X$1001),"")
A8: 5 | B8: =IF('04_DATA'!A5="","",'04_DATA'!A5) | C8: =IF('04_DATA'!A5="","",IF(AND('04_DATA'!G5=1,'04_DATA'!H5=1,'04_DATA'!I5>=3),"eligible","EXCLUDE")) | D8: =IF('04_DATA'!A5="","",37-COUNT('04_DATA'!$K5:$AU5)) | E8: =IF('04_DATA'!A5="","",(37-COUNT('04_DATA'!$K5:$AU5))/37) | F8: =IF('04_DATA'!A5="","",IF(AND(COUNT('04_DATA'!$K5:$AU5)=37,COUNTIF('04_DATA'!$K5:$AU5,INDEX('04_DATA'!$K5:$AU5,1))=37),"EXCLUDE","ok")) | G8: =IF('04_DATA'!A5="","",IF('04_DATA'!D5<PERCENTILE('04_DATA'!$D$2:$D$1001,0.05),"FLAG","ok")) | H8: =IF('04_DATA'!A5="","",IF(OR(C8="EXCLUDE",F8="EXCLUDE"),"Exclude under pre-specified rule",IF(E8>0.15,"Exclude: >15% missing",IF(G8="FLAG","Retain; test in robustness battery","Retain")))) | J8: Circular governance quality | K8: =IFERROR(AVERAGE('04_DATA'!$Y$2:$AD$1001),"") | L8: =IFERROR(STDEV('04_DATA'!$Y$2:$AD$1001),"") | M8: =IFERROR(MIN('04_DATA'!$Y$2:$AD$1001),"") | N8: =IFERROR(MAX('04_DATA'!$Y$2:$AD$1001),"") | O8: THE DESIGN DEPENDS ON THIS SD BEING LARGE. If it is small or the range is narrow, the interaction cannot be detected and you must say so before reporting any null.
A9: 6 | B9: =IF('04_DATA'!A6="","",'04_DATA'!A6) | C9: =IF('04_DATA'!A6="","",IF(AND('04_DATA'!G6=1,'04_DATA'!H6=1,'04_DATA'!I6>=3),"eligible","EXCLUDE")) | D9: =IF('04_DATA'!A6="","",37-COUNT('04_DATA'!$K6:$AU6)) | E9: =IF('04_DATA'!A6="","",(37-COUNT('04_DATA'!$K6:$AU6))/37) | F9: =IF('04_DATA'!A6="","",IF(AND(COUNT('04_DATA'!$K6:$AU6)=37,COUNTIF('04_DATA'!$K6:$AU6,INDEX('04_DATA'!$K6:$AU6,1))=37),"EXCLUDE","ok")) | G9: =IF('04_DATA'!A6="","",IF('04_DATA'!D6<PERCENTILE('04_DATA'!$D$2:$D$1001,0.05),"FLAG","ok")) | H9: =IF('04_DATA'!A6="","",IF(OR(C9="EXCLUDE",F9="EXCLUDE"),"Exclude under pre-specified rule",IF(E9>0.15,"Exclude: >15% missing",IF(G9="FLAG","Retain; test in robustness battery","Retain")))) | J9: Circular value-chain integration | K9: =IFERROR(AVERAGE('04_DATA'!$AE$2:$AJ$1001),"") | L9: =IFERROR(STDEV('04_DATA'!$AE$2:$AJ$1001),"") | M9: =IFERROR(MIN('04_DATA'!$AE$2:$AJ$1001),"") | N9: =IFERROR(MAX('04_DATA'!$AE$2:$AJ$1001),"")
A10: 7 | B10: =IF('04_DATA'!A7="","",'04_DATA'!A7) | C10: =IF('04_DATA'!A7="","",IF(AND('04_DATA'!G7=1,'04_DATA'!H7=1,'04_DATA'!I7>=3),"eligible","EXCLUDE")) | D10: =IF('04_DATA'!A7="","",37-COUNT('04_DATA'!$K7:$AU7)) | E10: =IF('04_DATA'!A7="","",(37-COUNT('04_DATA'!$K7:$AU7))/37) | F10: =IF('04_DATA'!A7="","",IF(AND(COUNT('04_DATA'!$K7:$AU7)=37,COUNTIF('04_DATA'!$K7:$AU7,INDEX('04_DATA'!$K7:$AU7,1))=37),"EXCLUDE","ok")) | G10: =IF('04_DATA'!A7="","",IF('04_DATA'!D7<PERCENTILE('04_DATA'!$D$2:$D$1001,0.05),"FLAG","ok")) | H10: =IF('04_DATA'!A7="","",IF(OR(C10="EXCLUDE",F10="EXCLUDE"),"Exclude under pre-specified rule",IF(E10>0.15,"Exclude: >15% missing",IF(G10="FLAG","Retain; test in robustness battery","Retain")))) | J10: Circular value creation performance | K10: =IFERROR(AVERAGE('04_DATA'!$AK$2:$AU$1001),"") | L10: =IFERROR(STDEV('04_DATA'!$AK$2:$AU$1001),"") | M10: =IFERROR(MIN('04_DATA'!$AK$2:$AU$1001),"") | N10: =IFERROR(MAX('04_DATA'!$AK$2:$AU$1001),"")
A11: 8 | B11: =IF('04_DATA'!A8="","",'04_DATA'!A8) | C11: =IF('04_DATA'!A8="","",IF(AND('04_DATA'!G8=1,'04_DATA'!H8=1,'04_DATA'!I8>=3),"eligible","EXCLUDE")) | D11: =IF('04_DATA'!A8="","",37-COUNT('04_DATA'!$K8:$AU8)) | E11: =IF('04_DATA'!A8="","",(37-COUNT('04_DATA'!$K8:$AU8))/37) | F11: =IF('04_DATA'!A8="","",IF(AND(COUNT('04_DATA'!$K8:$AU8)=37,COUNTIF('04_DATA'!$K8:$AU8,INDEX('04_DATA'!$K8:$AU8,1))=37),"EXCLUDE","ok")) | G11: =IF('04_DATA'!A8="","",IF('04_DATA'!D8<PERCENTILE('04_DATA'!$D$2:$D$1001,0.05),"FLAG","ok")) | H11: =IF('04_DATA'!A8="","",IF(OR(C11="EXCLUDE",F11="EXCLUDE"),"Exclude under pre-specified rule",IF(E11>0.15,"Exclude: >15% missing",IF(G11="FLAG","Retain; test in robustness battery","Retain")))) | J11: Digital traceability capability | K11: =IFERROR(AVERAGE('04_DATA'!$AV$2:$AX$1001),"") | L11: =IFERROR(STDEV('04_DATA'!$AV$2:$AX$1001),"") | M11: =IFERROR(MIN('04_DATA'!$AV$2:$AX$1001),"") | N11: =IFERROR(MAX('04_DATA'!$AV$2:$AX$1001),"")
A12: 9 | B12: =IF('04_DATA'!A9="","",'04_DATA'!A9) | C12: =IF('04_DATA'!A9="","",IF(AND('04_DATA'!G9=1,'04_DATA'!H9=1,'04_DATA'!I9>=3),"eligible","EXCLUDE")) | D12: =IF('04_DATA'!A9="","",37-COUNT('04_DATA'!$K9:$AU9)) | E12: =IF('04_DATA'!A9="","",(37-COUNT('04_DATA'!$K9:$AU9))/37) | F12: =IF('04_DATA'!A9="","",IF(AND(COUNT('04_DATA'!$K9:$AU9)=37,COUNTIF('04_DATA'!$K9:$AU9,INDEX('04_DATA'!$K9:$AU9,1))=37),"EXCLUDE","ok")) | G12: =IF('04_DATA'!A9="","",IF('04_DATA'!D9<PERCENTILE('04_DATA'!$D$2:$D$1001,0.05),"FLAG","ok")) | H12: =IF('04_DATA'!A9="","",IF(OR(C12="EXCLUDE",F12="EXCLUDE"),"Exclude under pre-specified rule",IF(E12>0.15,"Exclude: >15% missing",IF(G12="FLAG","Retain; test in robustness battery","Retain"))))
A13: 10 | B13: =IF('04_DATA'!A10="","",'04_DATA'!A10) | C13: =IF('04_DATA'!A10="","",IF(AND('04_DATA'!G10=1,'04_DATA'!H10=1,'04_DATA'!I10>=3),"eligible","EXCLUDE")) | D13: =IF('04_DATA'!A10="","",37-COUNT('04_DATA'!$K10:$AU10)) | E13: =IF('04_DATA'!A10="","",(37-COUNT('04_DATA'!$K10:$AU10))/37) | F13: =IF('04_DATA'!A10="","",IF(AND(COUNT('04_DATA'!$K10:$AU10)=37,COUNTIF('04_DATA'!$K10:$AU10,INDEX('04_DATA'!$K10:$AU10,1))=37),"EXCLUDE","ok")) | G13: =IF('04_DATA'!A10="","",IF('04_DATA'!D10<PERCENTILE('04_DATA'!$D$2:$D$1001,0.05),"FLAG","ok")) | H13: =IF('04_DATA'!A10="","",IF(OR(C13="EXCLUDE",F13="EXCLUDE"),"Exclude under pre-specified rule",IF(E13>0.15,"Exclude: >15% missing",IF(G13="FLAG","Retain; test in robustness battery","Retain"))))
A14: 11 | B14: =IF('04_DATA'!A11="","",'04_DATA'!A11) | C14: =IF('04_DATA'!A11="","",IF(AND('04_DATA'!G11=1,'04_DATA'!H11=1,'04_DATA'!I11>=3),"eligible","EXCLUDE")) | D14: =IF('04_DATA'!A11="","",37-COUNT('04_DATA'!$K11:$AU11)) | E14: =IF('04_DATA'!A11="","",(37-COUNT('04_DATA'!$K11:$AU11))/37) | F14: =IF('04_DATA'!A11="","",IF(AND(COUNT('04_DATA'!$K11:$AU11)=37,COUNTIF('04_DATA'!$K11:$AU11,INDEX('04_DATA'!$K11:$AU11,1))=37),"EXCLUDE","ok")) | G14: =IF('04_DATA'!A11="","",IF('04_DATA'!D11<PERCENTILE('04_DATA'!$D$2:$D$1001,0.05),"FLAG","ok")) | H14: =IF('04_DATA'!A11="","",IF(OR(C14="EXCLUDE",F14="EXCLUDE"),"Exclude under pre-specified rule",IF(E14>0.15,"Exclude: >15% missing",IF(G14="FLAG","Retain; test in robustness battery","Retain")))) | J14: MGA group sizes (need >=100 per group)
A15: 12 | B15: =IF('04_DATA'!A12="","",'04_DATA'!A12) | C15: =IF('04_DATA'!A12="","",IF(AND('04_DATA'!G12=1,'04_DATA'!H12=1,'04_DATA'!I12>=3),"eligible","EXCLUDE")) | D15: =IF('04_DATA'!A12="","",37-COUNT('04_DATA'!$K12:$AU12)) | E15: =IF('04_DATA'!A12="","",(37-COUNT('04_DATA'!$K12:$AU12))/37) | F15: =IF('04_DATA'!A12="","",IF(AND(COUNT('04_DATA'!$K12:$AU12)=37,COUNTIF('04_DATA'!$K12:$AU12,INDEX('04_DATA'!$K12:$AU12,1))=37),"EXCLUDE","ok")) | G15: =IF('04_DATA'!A12="","",IF('04_DATA'!D12<PERCENTILE('04_DATA'!$D$2:$D$1001,0.05),"FLAG","ok")) | H15: =IF('04_DATA'!A12="","",IF(OR(C15="EXCLUDE",F15="EXCLUDE"),"Exclude under pre-specified rule",IF(E15>0.15,"Exclude: >15% missing",IF(G15="FLAG","Retain; test in robustness battery","Retain")))) | J15: AFF = 1 (PO member) | K15: =COUNTIF('04_DATA'!$BK$2:$BK$1001,1) | L15: =IF(K15>=100,"viable","under-powered")
A16: 13 | B16: =IF('04_DATA'!A13="","",'04_DATA'!A13) | C16: =IF('04_DATA'!A13="","",IF(AND('04_DATA'!G13=1,'04_DATA'!H13=1,'04_DATA'!I13>=3),"eligible","EXCLUDE")) | D16: =IF('04_DATA'!A13="","",37-COUNT('04_DATA'!$K13:$AU13)) | E16: =IF('04_DATA'!A13="","",(37-COUNT('04_DATA'!$K13:$AU13))/37) | F16: =IF('04_DATA'!A13="","",IF(AND(COUNT('04_DATA'!$K13:$AU13)=37,COUNTIF('04_DATA'!$K13:$AU13,INDEX('04_DATA'!$K13:$AU13,1))=37),"EXCLUDE","ok")) | G16: =IF('04_DATA'!A13="","",IF('04_DATA'!D13<PERCENTILE('04_DATA'!$D$2:$D$1001,0.05),"FLAG","ok")) | H16: =IF('04_DATA'!A13="","",IF(OR(C16="EXCLUDE",F16="EXCLUDE"),"Exclude under pre-specified rule",IF(E16>0.15,"Exclude: >15% missing",IF(G16="FLAG","Retain; test in robustness battery","Retain")))) | J16: AFF = 0 (not affiliated) | K16: =COUNTIF('04_DATA'!$BK$2:$BK$1001,0) | L16: =IF(K16>=100,"viable","under-powered")
A17: 14 | B17: =IF('04_DATA'!A14="","",'04_DATA'!A14) | C17: =IF('04_DATA'!A14="","",IF(AND('04_DATA'!G14=1,'04_DATA'!H14=1,'04_DATA'!I14>=3),"eligible","EXCLUDE")) | D17: =IF('04_DATA'!A14="","",37-COUNT('04_DATA'!$K14:$AU14)) | E17: =IF('04_DATA'!A14="","",(37-COUNT('04_DATA'!$K14:$AU14))/37) | F17: =IF('04_DATA'!A14="","",IF(AND(COUNT('04_DATA'!$K14:$AU14)=37,COUNTIF('04_DATA'!$K14:$AU14,INDEX('04_DATA'!$K14:$AU14,1))=37),"EXCLUDE","ok")) | G17: =IF('04_DATA'!A14="","",IF('04_DATA'!D14<PERCENTILE('04_DATA'!$D$2:$D$1001,0.05),"FLAG","ok")) | H17: =IF('04_DATA'!A14="","",IF(OR(C17="EXCLUDE",F17="EXCLUDE"),"Exclude under pre-specified rule",IF(E17>0.15,"Exclude: >15% missing",IF(G17="FLAG","Retain; test in robustness battery","Retain")))) | J17: TIER 1 upstream | K17: =COUNTIF('04_DATA'!$F$2:$F$1001,1) | L17: =IF(K17>=100,"viable","under-powered")
A18: 15 | B18: =IF('04_DATA'!A15="","",'04_DATA'!A15) | C18: =IF('04_DATA'!A15="","",IF(AND('04_DATA'!G15=1,'04_DATA'!H15=1,'04_DATA'!I15>=3),"eligible","EXCLUDE")) | D18: =IF('04_DATA'!A15="","",37-COUNT('04_DATA'!$K15:$AU15)) | E18: =IF('04_DATA'!A15="","",(37-COUNT('04_DATA'!$K15:$AU15))/37) | F18: =IF('04_DATA'!A15="","",IF(AND(COUNT('04_DATA'!$K15:$AU15)=37,COUNTIF('04_DATA'!$K15:$AU15,INDEX('04_DATA'!$K15:$AU15,1))=37),"EXCLUDE","ok")) | G18: =IF('04_DATA'!A15="","",IF('04_DATA'!D15<PERCENTILE('04_DATA'!$D$2:$D$1001,0.05),"FLAG","ok")) | H18: =IF('04_DATA'!A15="","",IF(OR(C18="EXCLUDE",F18="EXCLUDE"),"Exclude under pre-specified rule",IF(E18>0.15,"Exclude: >15% missing",IF(G18="FLAG","Retain; test in robustness battery","Retain")))) | J18: TIER 2 midstream | K18: =COUNTIF('04_DATA'!$F$2:$F$1001,2) | L18: =IF(K18>=100,"viable","under-powered")
A19: 16 | B19: =IF('04_DATA'!A16="","",'04_DATA'!A16) | C19: =IF('04_DATA'!A16="","",IF(AND('04_DATA'!G16=1,'04_DATA'!H16=1,'04_DATA'!I16>=3),"eligible","EXCLUDE")) | D19: =IF('04_DATA'!A16="","",37-COUNT('04_DATA'!$K16:$AU16)) | E19: =IF('04_DATA'!A16="","",(37-COUNT('04_DATA'!$K16:$AU16))/37) | F19: =IF('04_DATA'!A16="","",IF(AND(COUNT('04_DATA'!$K16:$AU16)=37,COUNTIF('04_DATA'!$K16:$AU16,INDEX('04_DATA'!$K16:$AU16,1))=37),"EXCLUDE","ok")) | G19: =IF('04_DATA'!A16="","",IF('04_DATA'!D16<PERCENTILE('04_DATA'!$D$2:$D$1001,0.05),"FLAG","ok")) | H19: =IF('04_DATA'!A16="","",IF(OR(C19="EXCLUDE",F19="EXCLUDE"),"Exclude under pre-specified rule",IF(E19>0.15,"Exclude: >15% missing",IF(G19="FLAG","Retain; test in robustness battery","Retain")))) | J19: TIER 3 processing / recovery | K19: =COUNTIF('04_DATA'!$F$2:$F$1001,3) | L19: =IF(K19>=100,"viable","under-powered")
A20: 17 | B20: =IF('04_DATA'!A17="","",'04_DATA'!A17) | C20: =IF('04_DATA'!A17="","",IF(AND('04_DATA'!G17=1,'04_DATA'!H17=1,'04_DATA'!I17>=3),"eligible","EXCLUDE")) | D20: =IF('04_DATA'!A17="","",37-COUNT('04_DATA'!$K17:$AU17)) | E20: =IF('04_DATA'!A17="","",(37-COUNT('04_DATA'!$K17:$AU17))/37) | F20: =IF('04_DATA'!A17="","",IF(AND(COUNT('04_DATA'!$K17:$AU17)=37,COUNTIF('04_DATA'!$K17:$AU17,INDEX('04_DATA'!$K17:$AU17,1))=37),"EXCLUDE","ok")) | G20: =IF('04_DATA'!A17="","",IF('04_DATA'!D17<PERCENTILE('04_DATA'!$D$2:$D$1001,0.05),"FLAG","ok")) | H20: =IF('04_DATA'!A17="","",IF(OR(C20="EXCLUDE",F20="EXCLUDE"),"Exclude under pre-specified rule",IF(E20>0.15,"Exclude: >15% missing",IF(G20="FLAG","Retain; test in robustness battery","Retain")))) | J20: TIER 4 downstream | K20: =COUNTIF('04_DATA'!$F$2:$F$1001,4) | L20: =IF(K20>=100,"viable","under-powered")
A21: 18 | B21: =IF('04_DATA'!A18="","",'04_DATA'!A18) | C21: =IF('04_DATA'!A18="","",IF(AND('04_DATA'!G18=1,'04_DATA'!H18=1,'04_DATA'!I18>=3),"eligible","EXCLUDE")) | D21: =IF('04_DATA'!A18="","",37-COUNT('04_DATA'!$K18:$AU18)) | E21: =IF('04_DATA'!A18="","",(37-COUNT('04_DATA'!$K18:$AU18))/37) | F21: =IF('04_DATA'!A18="","",IF(AND(COUNT('04_DATA'!$K18:$AU18)=37,COUNTIF('04_DATA'!$K18:$AU18,INDEX('04_DATA'!$K18:$AU18,1))=37),"EXCLUDE","ok")) | G21: =IF('04_DATA'!A18="","",IF('04_DATA'!D18<PERCENTILE('04_DATA'!$D$2:$D$1001,0.05),"FLAG","ok")) | H21: =IF('04_DATA'!A18="","",IF(OR(C21="EXCLUDE",F21="EXCLUDE"),"Exclude under pre-specified rule",IF(E21>0.15,"Exclude: >15% missing",IF(G21="FLAG","Retain; test in robustness battery","Retain")))) | J21: Do NOT run the producer-versus-processor comparison: with ~70 processors it needs β ≥ 0.30. Your manuscript states it will not be conducted and why. Honour that.
A22: 19 | B22: =IF('04_DATA'!A19="","",'04_DATA'!A19) | C22: =IF('04_DATA'!A19="","",IF(AND('04_DATA'!G19=1,'04_DATA'!H19=1,'04_DATA'!I19>=3),"eligible","EXCLUDE")) | D22: =IF('04_DATA'!A19="","",37-COUNT('04_DATA'!$K19:$AU19)) | E22: =IF('04_DATA'!A19="","",(37-COUNT('04_DATA'!$K19:$AU19))/37) | F22: =IF('04_DATA'!A19="","",IF(AND(COUNT('04_DATA'!$K19:$AU19)=37,COUNTIF('04_DATA'!$K19:$AU19,INDEX('04_DATA'!$K19:$AU19,1))=37),"EXCLUDE","ok")) | G22: =IF('04_DATA'!A19="","",IF('04_DATA'!D19<PERCENTILE('04_DATA'!$D$2:$D$1001,0.05),"FLAG","ok")) | H22: =IF('04_DATA'!A19="","",IF(OR(C22="EXCLUDE",F22="EXCLUDE"),"Exclude under pre-specified rule",IF(E22>0.15,"Exclude: >15% missing",IF(G22="FLAG","Retain; test in robustness battery","Retain"))))
A23: 20 | B23: =IF('04_DATA'!A20="","",'04_DATA'!A20) | C23: =IF('04_DATA'!A20="","",IF(AND('04_DATA'!G20=1,'04_DATA'!H20=1,'04_DATA'!I20>=3),"eligible","EXCLUDE")) | D23: =IF('04_DATA'!A20="","",37-COUNT('04_DATA'!$K20:$AU20)) | E23: =IF('04_DATA'!A20="","",(37-COUNT('04_DATA'!$K20:$AU20))/37) | F23: =IF('04_DATA'!A20="","",IF(AND(COUNT('04_DATA'!$K20:$AU20)=37,COUNTIF('04_DATA'!$K20:$AU20,INDEX('04_DATA'!$K20:$AU20,1))=37),"EXCLUDE","ok")) | G23: =IF('04_DATA'!A20="","",IF('04_DATA'!D20<PERCENTILE('04_DATA'!$D$2:$D$1001,0.05),"FLAG","ok")) | H23: =IF('04_DATA'!A20="","",IF(OR(C23="EXCLUDE",F23="EXCLUDE"),"Exclude under pre-specified rule",IF(E23>0.15,"Exclude: >15% missing",IF(G23="FLAG","Retain; test in robustness battery","Retain"))))
A24: 21 | B24: =IF('04_DATA'!A21="","",'04_DATA'!A21) | C24: =IF('04_DATA'!A21="","",IF(AND('04_DATA'!G21=1,'04_DATA'!H21=1,'04_DATA'!I21>=3),"eligible","EXCLUDE")) | D24: =IF('04_DATA'!A21="","",37-COUNT('04_DATA'!$K21:$AU21)) | E24: =IF('04_DATA'!A21="","",(37-COUNT('04_DATA'!$K21:$AU21))/37) | F24: =IF('04_DATA'!A21="","",IF(AND(COUNT('04_DATA'!$K21:$AU21)=37,COUNTIF('04_DATA'!$K21:$AU21,INDEX('04_DATA'!$K21:$AU21,1))=37),"EXCLUDE","ok")) | G24: =IF('04_DATA'!A21="","",IF('04_DATA'!D21<PERCENTILE('04_DATA'!$D$2:$D$1001,0.05),"FLAG","ok")) | H24: =IF('04_DATA'!A21="","",IF(OR(C24="EXCLUDE",F24="EXCLUDE"),"Exclude under pre-specified rule",IF(E24>0.15,"Exclude: >15% missing",IF(G24="FLAG","Retain; test in robustness battery","Retain"))))
A25: 22 | B25: =IF('04_DATA'!A22="","",'04_DATA'!A22) | C25: =IF('04_DATA'!A22="","",IF(AND('04_DATA'!G22=1,'04_DATA'!H22=1,'04_DATA'!I22>=3),"eligible","EXCLUDE")) | D25: =IF('04_DATA'!A22="","",37-COUNT('04_DATA'!$K22:$AU22)) | E25: =IF('04_DATA'!A22="","",(37-COUNT('04_DATA'!$K22:$AU22))/37) | F25: =IF('04_DATA'!A22="","",IF(AND(COUNT('04_DATA'!$K22:$AU22)=37,COUNTIF('04_DATA'!$K22:$AU22,INDEX('04_DATA'!$K22:$AU22,1))=37),"EXCLUDE","ok")) | G25: =IF('04_DATA'!A22="","",IF('04_DATA'!D22<PERCENTILE('04_DATA'!$D$2:$D$1001,0.05),"FLAG","ok")) | H25: =IF('04_DATA'!A22="","",IF(OR(C25="EXCLUDE",F25="EXCLUDE"),"Exclude under pre-specified rule",IF(E25>0.15,"Exclude: >15% missing",IF(G25="FLAG","Retain; test in robustness battery","Retain"))))
A26: 23 | B26: =IF('04_DATA'!A23="","",'04_DATA'!A23) | C26: =IF('04_DATA'!A23="","",IF(AND('04_DATA'!G23=1,'04_DATA'!H23=1,'04_DATA'!I23>=3),"eligible","EXCLUDE")) | D26: =IF('04_DATA'!A23="","",37-COUNT('04_DATA'!$K23:$AU23)) | E26: =IF('04_DATA'!A23="","",(37-COUNT('04_DATA'!$K23:$AU23))/37) | F26: =IF('04_DATA'!A23="","",IF(AND(COUNT('04_DATA'!$K23:$AU23)=37,COUNTIF('04_DATA'!$K23:$AU23,INDEX('04_DATA'!$K23:$AU23,1))=37),"EXCLUDE","ok")) | G26: =IF('04_DATA'!A23="","",IF('04_DATA'!D23<PERCENTILE('04_DATA'!$D$2:$D$1001,0.05),"FLAG","ok")) | H26: =IF('04_DATA'!A23="","",IF(OR(C26="EXCLUDE",F26="EXCLUDE"),"Exclude under pre-specified rule",IF(E26>0.15,"Exclude: >15% missing",IF(G26="FLAG","Retain; test in robustness battery","Retain"))))
A27: 24 | B27: =IF('04_DATA'!A24="","",'04_DATA'!A24) | C27: =IF('04_DATA'!A24="","",IF(AND('04_DATA'!G24=1,'04_DATA'!H24=1,'04_DATA'!I24>=3),"eligible","EXCLUDE")) | D27: =IF('04_DATA'!A24="","",37-COUNT('04_DATA'!$K24:$AU24)) | E27: =IF('04_DATA'!A24="","",(37-COUNT('04_DATA'!$K24:$AU24))/37) | F27: =IF('04_DATA'!A24="","",IF(AND(COUNT('04_DATA'!$K24:$AU24)=37,COUNTIF('04_DATA'!$K24:$AU24,INDEX('04_DATA'!$K24:$AU24,1))=37),"EXCLUDE","ok")) | G27: =IF('04_DATA'!A24="","",IF('04_DATA'!D24<PERCENTILE('04_DATA'!$D$2:$D$1001,0.05),"FLAG","ok")) | H27: =IF('04_DATA'!A24="","",IF(OR(C27="EXCLUDE",F27="EXCLUDE"),"Exclude under pre-specified rule",IF(E27>0.15,"Exclude: >15% missing",IF(G27="FLAG","Retain; test in robustness battery","Retain"))))
A28: 25 | B28: =IF('04_DATA'!A25="","",'04_DATA'!A25) | C28: =IF('04_DATA'!A25="","",IF(AND('04_DATA'!G25=1,'04_DATA'!H25=1,'04_DATA'!I25>=3),"eligible","EXCLUDE")) | D28: =IF('04_DATA'!A25="","",37-COUNT('04_DATA'!$K25:$AU25)) | E28: =IF('04_DATA'!A25="","",(37-COUNT('04_DATA'!$K25:$AU25))/37) | F28: =IF('04_DATA'!A25="","",IF(AND(COUNT('04_DATA'!$K25:$AU25)=37,COUNTIF('04_DATA'!$K25:$AU25,INDEX('04_DATA'!$K25:$AU25,1))=37),"EXCLUDE","ok")) | G28: =IF('04_DATA'!A25="","",IF('04_DATA'!D25<PERCENTILE('04_DATA'!$D$2:$D$1001,0.05),"FLAG","ok")) | H28: =IF('04_DATA'!A25="","",IF(OR(C28="EXCLUDE",F28="EXCLUDE"),"Exclude under pre-specified rule",IF(E28>0.15,"Exclude: >15% missing",IF(G28="FLAG","Retain; test in robustness battery","Retain"))))
A29: 26 | B29: =IF('04_DATA'!A26="","",'04_DATA'!A26) | C29: =IF('04_DATA'!A26="","",IF(AND('04_DATA'!G26=1,'04_DATA'!H26=1,'04_DATA'!I26>=3),"eligible","EXCLUDE")) | D29: =IF('04_DATA'!A26="","",37-COUNT('04_DATA'!$K26:$AU26)) | E29: =IF('04_DATA'!A26="","",(37-COUNT('04_DATA'!$K26:$AU26))/37) | F29: =IF('04_DATA'!A26="","",IF(AND(COUNT('04_DATA'!$K26:$AU26)=37,COUNTIF('04_DATA'!$K26:$AU26,INDEX('04_DATA'!$K26:$AU26,1))=37),"EXCLUDE","ok")) | G29: =IF('04_DATA'!A26="","",IF('04_DATA'!D26<PERCENTILE('04_DATA'!$D$2:$D$1001,0.05),"FLAG","ok")) | H29: =IF('04_DATA'!A26="","",IF(OR(C29="EXCLUDE",F29="EXCLUDE"),"Exclude under pre-specified rule",IF(E29>0.15,"Exclude: >15% missing",IF(G29="FLAG","Retain; test in robustness battery","Retain"))))
A30: 27 | B30: =IF('04_DATA'!A27="","",'04_DATA'!A27) | C30: =IF('04_DATA'!A27="","",IF(AND('04_DATA'!G27=1,'04_DATA'!H27=1,'04_DATA'!I27>=3),"eligible","EXCLUDE")) | D30: =IF('04_DATA'!A27="","",37-COUNT('04_DATA'!$K27:$AU27)) | E30: =IF('04_DATA'!A27="","",(37-COUNT('04_DATA'!$K27:$AU27))/37) | F30: =IF('04_DATA'!A27="","",IF(AND(COUNT('04_DATA'!$K27:$AU27)=37,COUNTIF('04_DATA'!$K27:$AU27,INDEX('04_DATA'!$K27:$AU27,1))=37),"EXCLUDE","ok")) | G30: =IF('04_DATA'!A27="","",IF('04_DATA'!D27<PERCENTILE('04_DATA'!$D$2:$D$1001,0.05),"FLAG","ok")) | H30: =IF('04_DATA'!A27="","",IF(OR(C30="EXCLUDE",F30="EXCLUDE"),"Exclude under pre-specified rule",IF(E30>0.15,"Exclude: >15% missing",IF(G30="FLAG","Retain; test in robustness battery","Retain"))))
A31: 28 | B31: =IF('04_DATA'!A28="","",'04_DATA'!A28) | C31: =IF('04_DATA'!A28="","",IF(AND('04_DATA'!G28=1,'04_DATA'!H28=1,'04_DATA'!I28>=3),"eligible","EXCLUDE")) | D31: =IF('04_DATA'!A28="","",37-COUNT('04_DATA'!$K28:$AU28)) | E31: =IF('04_DATA'!A28="","",(37-COUNT('04_DATA'!$K28:$AU28))/37) | F31: =IF('04_DATA'!A28="","",IF(AND(COUNT('04_DATA'!$K28:$AU28)=37,COUNTIF('04_DATA'!$K28:$AU28,INDEX('04_DATA'!$K28:$AU28,1))=37),"EXCLUDE","ok")) | G31: =IF('04_DATA'!A28="","",IF('04_DATA'!D28<PERCENTILE('04_DATA'!$D$2:$D$1001,0.05),"FLAG","ok")) | H31: =IF('04_DATA'!A28="","",IF(OR(C31="EXCLUDE",F31="EXCLUDE"),"Exclude under pre-specified rule",IF(E31>0.15,"Exclude: >15% missing",IF(G31="FLAG","Retain; test in robustness battery","Retain"))))
A32: 29 | B32: =IF('04_DATA'!A29="","",'04_DATA'!A29) | C32: =IF('04_DATA'!A29="","",IF(AND('04_DATA'!G29=1,'04_DATA'!H29=1,'04_DATA'!I29>=3),"eligible","EXCLUDE")) | D32: =IF('04_DATA'!A29="","",37-COUNT('04_DATA'!$K29:$AU29)) | E32: =IF('04_DATA'!A29="","",(37-COUNT('04_DATA'!$K29:$AU29))/37) | F32: =IF('04_DATA'!A29="","",IF(AND(COUNT('04_DATA'!$K29:$AU29)=37,COUNTIF('04_DATA'!$K29:$AU29,INDEX('04_DATA'!$K29:$AU29,1))=37),"EXCLUDE","ok")) | G32: =IF('04_DATA'!A29="","",IF('04_DATA'!D29<PERCENTILE('04_DATA'!$D$2:$D$1001,0.05),"FLAG","ok")) | H32: =IF('04_DATA'!A29="","",IF(OR(C32="EXCLUDE",F32="EXCLUDE"),"Exclude under pre-specified rule",IF(E32>0.15,"Exclude: >15% missing",IF(G32="FLAG","Retain; test in robustness battery","Retain"))))
A33: 30 | B33: =IF('04_DATA'!A30="","",'04_DATA'!A30) | C33: =IF('04_DATA'!A30="","",IF(AND('04_DATA'!G30=1,'04_DATA'!H30=1,'04_DATA'!I30>=3),"eligible","EXCLUDE")) | D33: =IF('04_DATA'!A30="","",37-COUNT('04_DATA'!$K30:$AU30)) | E33: =IF('04_DATA'!A30="","",(37-COUNT('04_DATA'!$K30:$AU30))/37) | F33: =IF('04_DATA'!A30="","",IF(AND(COUNT('04_DATA'!$K30:$AU30)=37,COUNTIF('04_DATA'!$K30:$AU30,INDEX('04_DATA'!$K30:$AU30,1))=37),"EXCLUDE","ok")) | G33: =IF('04_DATA'!A30="","",IF('04_DATA'!D30<PERCENTILE('04_DATA'!$D$2:$D$1001,0.05),"FLAG","ok")) | H33: =IF('04_DATA'!A30="","",IF(OR(C33="EXCLUDE",F33="EXCLUDE"),"Exclude under pre-specified rule",IF(E33>0.15,"Exclude: >15% missing",IF(G33="FLAG","Retain; test in robustness battery","Retain"))))
... A1004: 1001 | B1004: =IF('04_DATA'!A1001="","",'04_DATA'!A1001) | C1004: =IF('04_DATA'!A1001="","",IF(AND('04_DATA'!G1001=1,'04_DATA'!H1001=1,'04_DATA'!I1001>=3),"eligible","EXCLUDE")) | D1004: =IF('04_DATA'!A1001="","",37-COUNT('04_DATA'!$K1001:$AU1001)) | E1004: =IF('04_DATA'!A1001="","",(37-COUNT('04_DATA'!$K1001:$AU1001))/37) | F1004: =IF('04_DATA'!A1001="","",IF(AND(COUNT('04_DATA'!$K1001:$AU1001)=37,COUNTIF('04_DATA'!$K1001:$AU1001,INDEX('04_DATA'!$K1001:$AU1001,1))=37),"EXCLUDE","ok")) | G1004: =IF('04_DATA'!A1001="","",IF('04_DATA'!D1001<PERCENTILE('04_DATA'!$D$2:$D$1001,0.05),"FLAG","ok")) | H1004: =IF('04_DATA'!A1001="","",IF(OR(C1004="EXCLUDE",F1004="EXCLUDE"),"Exclude under pre-specified rule",IF(E1004>0.15,"Exclude: >15% missing",IF(G1004="FLAG","Retain; test in robustness battery","Retain"))))
